---
layout: post
title: Go 异常处理.md
categories: [Go]
description: Go
keywords: Go
mermaid: false
sequence: false
flow: false
mathjax: false
mindmap: false
mindmap2: false
---
# Go 异常处理

## 异常

以相同实参调用两次`errors.New`函数返回的两个`error`值是不相等的。`errors.New`函数会复制输入的字符串实参至一个局部变量并取此局部变量的指针作为返回`error`值的动态值，两次调用会产生两个不同的指针。

```go
func TestCompareSameValueError(t *testing.T) {
	notfound := "not found"
	a, b := errors.New(notfound), errors.New(notfound)
	fmt.Println(a == b) // false
}
```



## 恐慌和恢复

### 概述

Go不支持异常抛出和捕获，而是推荐使用返回值显式返回错误。不过，Go支持一套和异常抛出/捕获类似的机制，此机制称为恐慌/恢复（panic/recover）机制。

调用内置函数`panic`来产生一个恐慌以使当前协程进入恐慌状况，进入恐慌状况是另一种使当前函数调用开始返回的途径。一旦函数调用产生一个恐慌，此函数调用将立即进入它的退出阶段。通过在一个延迟函数调用之中调用内置函数`recover`，当前协程中的一个恐慌可以被消除，从而使得当前协程重新进入正常状况。如果一个协程在恐慌状况下退出，它将使整个程序崩溃。

内置函数`panic`和`recover`的声明原型如下：

```go
func panic(v interface{})
func recover() interface{} // 一个recover函数的返回值为其所恢复的恐慌在产生时被一个panic函数调用所消费的参数
```



下面这个例子展示了如何产生一个恐慌和如何消除一个恐慌：

```go
package main

import "fmt"

func main() {
	defer func() {
		fmt.Println("正常退出")
	}()
	fmt.Println("嗨！")
	defer func() {
		v := recover()
		fmt.Println("恐慌被恢复了：", v)
	}()
	panic("拜拜！") // 产生一个恐慌
	fmt.Println("执行不到这里")
}
```

输出结果：

```
嗨！
恐慌被恢复了： 拜拜！
正常退出
```



下面的例子在一个新协程里面产生了一个恐慌，并且此协程在恐慌状况下退出，所以整个程序崩溃了。

```go
package main

import (
	"fmt"
	"time"
)

func main() {
	fmt.Println("hi!")

	go func() {
		time.Sleep(time.Second)
		panic(123)
	}()

	for {
		time.Sleep(time.Second)
	}
}
```

运行之，输出如下：

```
hi!
panic: 123

goroutine 5 [running]:
...
```



Go运行时（runtime）会在若干情形下产生恐慌，比如一个整数被0除的时候，下面这个程序将崩溃退出。

```go
package main

func main() {
	a, b := 1, 0
	_ = a/b
}
```

它的输出：

```
panic: runtime error: integer divide by zero

goroutine 1 [running]:
...
```



一般说来，恐慌用来表示正常情况下不应该发生的逻辑错误，如果这样的一个错误在运行时发生了，则它肯定是由于某个bug引起的。另一方面，非逻辑错误是现实中难以避免的错误，它们不应该导致恐慌。

对于官方标准编译器来说，很多致命性错误（比如栈溢出和内存不足）不能被恢复，它们一旦产生，程序将崩溃。



### 使用示例

#### 避免恐慌导致程序崩溃

这可能是最常见的panic/recover用例了，此用例广泛地使用于并发程序中，尤其是响应大量用户请求的应用。一个例子：

```go
package main

import "errors"
import "log"
import "net"

func main() {
	listener, err := net.Listen("tcp", ":12345")
	if err != nil {
		log.Fatalln(err)
	}
	for {
		conn, err := listener.Accept()
		if err != nil {
			log.Println(err)
		}
		// 在一个新协程中处理客户端连接。
		go ClientHandler(conn)
	}
}

func ClientHandler(c net.Conn) {
	defer func() {
		if v := recover(); v != nil {
			log.Println("捕获了一个恐慌：", v)
			log.Println("防止了程序崩溃")
		}
		c.Close()
	}()
	panic("未知错误") // 演示目的产生的一个恐慌
}
```



运行此服务器程序，并在另一个终端窗口运行`telnet localhost 12345`，可以观察到服务器程序不会因为客户连接处理协程中的产生的恐慌而导致崩溃。如果在上例中不捕获客户连接处理协程中的潜在恐慌，则这样的恐慌将使整个程序崩溃。



#### 自动重启因为恐慌而退出的协程

当在一个协程将要退出时，程序侦测到此协程是因为一个恐慌而导致此次退出时，可以立即重新创建一个相同功能的协程。一个例子：

```go
package main

import "log"
import "time"

func shouldNotExit() {
	for {
		time.Sleep(time.Second) // 模拟一个工作负载
		// 模拟一个未预料到的恐慌。
		if time.Now().UnixNano() & 0x3 == 0 {
			panic("unexpected situation")
		}
	}
}

func NeverExit(name string, f func()) {
	defer func() {
		if v := recover(); v != nil { // 侦测到一个恐慌
			log.Printf("协程%s崩溃了，准备重启一个", name)
			go NeverExit(name, f) // 重启一个同功能协程
		}
	}()
	f()
}

func main() {
	log.SetFlags(0)
	go NeverExit("job#A", shouldNotExit)
	go NeverExit("job#B", shouldNotExit)
	select{} // 永久阻塞主线程
}
```



#### 使用panic/recover模拟长程跳转

有时可以使用`panic`/`recover`函数调用来模拟跨函数跳转，尽管一般这种方式并不推荐使用。这种跳转方式的可读性不高，代码效率也不是很高，唯一的好处是它有时可以使代码看上去不是很啰嗦。在下面这个例子中，一旦一个恐慌在一个内嵌函数中产生，当前协程中的执行将会跳转到延迟调用处。

```go
package main

import "fmt"

func main() {
	n := func () (result int)  {
		defer func() {
			if v := recover(); v != nil {
				if n, ok := v.(int); ok {
					result = n
				}
			}
		}()

		func () {
			func () {
				func () {
					// ...
					panic(123) // 用恐慌来表示成功返回
				}()
				// ...
			}()
		}()
		// ...
		return 0
	}()
	fmt.Println(n) // 123
}
```



#### 使用panic/recover来减少错误检查代码

```go
func doSomething() (err error) {
	defer func() {
		switch e := recover().(type) {
		case nil:
		case error:
			err = e
		default:
			panic(e) // 重新抛出此恐慌
		}
	}()

	doStep1()
	doStep2()
	doStep3()
	doStep4()
	doStep5()

	return
}

// 在现实中，各个doStepN函数的原型可能不同。这里，每个doStepN函数的行为如下：
// * 如果已经成功，则调用panic(nil)来制造一个恐慌以示不需继续；
// * 如果本步失败，则调用panic(err)来制造一个恐慌以示不需继续；
// * 不制造任何恐慌表示继续下一步。
func doStepN() {
	...
	if err != nil {
		panic(err)
	}
	...
	if done {
		panic(nil)
	}
}
```



下面这段同功能的代码比上面这段代码看上去要啰嗦一些。

```go
func doSomething() (err error) {
	shouldContinue, err := doStep1()
	if !shouldContinue {
		return err
	}
	shouldContinue, err = doStep2()
	if !shouldContinue {
		return err
	}
	shouldContinue, err = doStep3()
	if !shouldContinue {
		return err
	}
	shouldContinue, err = doStep4()
	if !shouldContinue {
		return err
	}
	shouldContinue, err = doStep5()
	if !shouldContinue {
		return err
	}

	return
}

// 如果返回值err不为nil，则shouldContinue一定为true，如果shouldContinue为true，返回值err可能为nil或者非nil。
func doStepN() (shouldContinue bool, err error) {
	...
	if err != nil {
		return false, err
	}
	...
	if done {
		return false, nil
	}
	return true, nil
}
```



这种`panic`/`recover`函数调用的使用方式一般并不推荐使用，因为它的效率略低一些，并且这种用法不太符合Go编程习俗。另外需要注意的是：从Go 1.21开始，一个`panic(nil)`调用将变得和`panic(new(runtime.PanicNilError))`等价，所以，从Go 1.21开始，上面代码中的延迟函数调用应该被重写为：

```go
import "runtime"

...

func doSomething() (err error) {
	defer func() {
		switch e := recover().(type) {
		case nil, *runtime.PanicNilError:
		case error:
			err = e
		default:
			panic(e) // 重新抛出此恐慌
		}
	}()

	doStep1()
	...
}
```



### 恐慌和恢复原理

#### 函数调用的退出阶段

在Go中，函数调用在其退出完毕之前可能将经历一个退出阶段。在此退出阶段，所有在执行此函数调用期间被推入延迟调用队列的延迟函数调用将按照它们的推入顺序的逆序被执行。当这些延迟函数调用都退出完毕之后，此函数调用的退出阶段也就结束了，或者说此函数调用也退出完毕了。退出阶段有时候也被称为返回阶段。一个函数调用可能通过三种途径进入它的退出阶段：

1. 此调用正常返回；
2. 当此调用中产生了一个恐慌；
3. 当`runtime.Goexit`函数在此调用中被调用并且退出完毕，一般`runtime.Goexit()`函数不希望在主协程中调用。

```go
import (
	"fmt"
	"runtime"
)

func f0() int {
	var x = 1
	defer fmt.Println("正常退出：", x)
	x++
	return x // 正常返回后进入它的退出阶段
}

func f1() {
	var x = 1
	defer fmt.Println("正常退出：", x)
	x++ // 正常返回后进入它的退出阶段
}

func f2() {
	var x, y = 1, 0
	defer fmt.Println("因恐慌而退出：", x)
	x = x / y // 将产生一个恐慌，在“被零除”恐慌产生之后进入它的退出阶段
	x++       // 执行不到
}

func f3() int {
	x := 1
	defer fmt.Println("因Goexit调用而退出：", x)
	x++
	runtime.Goexit() // 在`runtime.Goexit`函数调用退出完毕之后进入它的退出阶段
	return x+x // 执行不到
}
```



#### 函数调用关联恐慌和Goexit信号

当函数调用中直接产生了恐慌时，可以认为此（尚未被恢复的）恐慌将和此函数调用相关联起来。类似地，当函数调用直接调用了`runtime.Goexit`函数，则`runtime.Goexit`函数返回完毕之后，可以认为一个Goexit信号将和此函数调用相关联起来。当恐慌或者Goexit信号和函数调用相关联之后，此函数调用将立即进入它的退出阶段。

在任何一个给定时刻，一个函数调用最多只能和一个未恢复的恐慌相关联。如果一个调用正和一个未恢复的恐慌相关联，则：

- 在此恐慌被恢复之后，此调用将不再和任何恐慌相关联。
- 当在此函数调用中产生了一个新的恐慌，此新恐慌将替换原来的未被恢复的恐慌做为和此函数调用相关联的恐慌。

比如，在下面这个例子中，最终被恢复的恐慌是恐慌3，它是最后一个和`main`函数调用相关联的恐慌。

```go
package main

import "fmt"

func main() {
	defer func() {
		fmt.Println(recover()) // 3
	}()
	
	defer panic(3) // 将替换恐慌2
	defer panic(2) // 将替换恐慌1
	defer panic(1) // 将替换恐慌0
	panic(0)
}
```



恐慌是可以被恢复的，但是，Goexit信号是不能被取消的。因为Goexit信号不可被取消，争论函数调用是否最多只能和一个Goexit信号相关联是没有意义和没有必要的。



在某个时刻，一个协程中可能共存多个未被恢复的恐慌，尽管在实际编程中并不常见。每个未被恢复的恐慌和此协程的调用堆栈中的一个尚未退出的函数调用相关联。当仍和一个未被恢复的恐慌相关联的一个内层函数调用退出完毕之后，此未被恢复的恐慌将传播到调用此内层函数调用的外层函数调用中。这和在此外层函数调用中直接产生一个新的恐慌的效果是一样的。也就是说，

- 如果此外层函数已经和一个未被恢复的旧恐慌相关联，则传播出来的新恐慌将替换此旧恐慌并和此外层函数调用相关联起来。对于这种情形，此外层函数调用肯定已经进入了它的退出阶段（刚提及的内层函数肯定就是被延迟调用的），这时延迟调用队列中的下一个延迟调用将被执行。
- 如果此外层函数尚未和一个未被恢复的旧恐慌相关联，则传播出来的恐慌将和此外层函数调用相关联起来。对于这种情形，如果此外层函数调用尚未进入它的退出阶段，则它将立即进入。



所以，当一个协程完成完毕后，此协程中最多只有一个尚未被恢复的恐慌。如果一个协程带着一个尚未被恢复的恐慌退出完毕，则这将使整个程序崩溃，此恐慌信息将在程序崩溃的时候被打印出来。

在一个函数调用被执行的起始时刻，此调用将没有任何恐慌和Goexit信号和它相关联，这个事实和此函数调用的外层调用是否已经进入退出阶段无关。当然，在此函数调用的执行过程中，恐慌可能产生，`runtime.Goexit`函数也可能被调用，因此恐慌和Goexit信号以后可能和此调用相关联起来。下面这个例子程序在运行时将崩溃，因为新开辟的协程在退出完毕时仍带有一个未被恢复的恐慌。

```go
package main

func main() {
	// 新开辟一个协程。
	go func() {
		// 一个匿名函数调用，当它退出完毕时，恐慌2将传播到此新协程的入口。调用中，并且替换掉恐慌0。恐慌2永不会被恢复。
		defer func() {
			// 上一个例子中已经解释过了：恐慌2将替换恐慌1.
			defer panic(2)
			
			// 当此匿名函数调用退出完毕后，恐慌1将传播到刚提到的外层匿名函数调用中并与之关联起来。
			func () {
				panic(1)
				// 在恐慌1产生后，此新开辟的协程中将共存两个未被恢复的恐慌。其中一个（恐慌0）和此协程的入口函数调用相关联；另一个（恐慌1）和当前这个匿名调用相关联。
			}()
		}()
		panic(0)
	}()
	
	select{}
}
```



此程序的输出（当使用标准编译器1.23版本编译）：

```
panic: 0
	panic: 1
	panic: 2

...
```



此输出的格式并非很完美，它容易让一些程序员误认为恐慌0是最终未被恢复的恐慌，而事实上，恐慌2才是最终未被恢复的恐慌。

类似地，当一个和Goexit信号相关联的内层函数调用退出完毕后，此Goexit信号也将传播到外层函数调用中，并和外层函数调用相关联起来。如果外层函数调用尚未进入退出阶段，则其将立即进入。当一个Goexit信号和一个函数调用相关联起来的时候，如果此函数调用正在和一个未被恢复的恐慌相关联着，则此恐慌将被恢复。比如下面这个程序将正常退出并打印出`<nil>`，因为恐慌`bye`被Goexit信号恢复了。

```go
package main

import (
	"fmt"
	"runtime"
)

func f() {
	defer func() {
		fmt.Println(recover())
	}()

	// 此调用产生的Goexit信号恢复之前产生的恐慌。
	defer runtime.Goexit()
	panic("bye")
}

func main() {
	go f()
	
	for runtime.NumGoroutine() > 1 {
		runtime.Gosched()
	}
}
```



#### 一些`recover`调用相当于空操作

内置`recover`函数必须在合适的位置调用才能发挥作用；否则，它的调用相当于空操作（No-Op）。 比如，在下面这个程序中，没有一个`recover`函数调用恢复了恐慌`bye`。

```go
package main

func main() {
	defer func() {
		defer func() {
			recover() // 空操作
		}()
	}()
	defer func() {
		func() {
			recover() // 空操作
		}()
	}()
	func() {
		defer func() {
			recover() // 空操作
		}()
	}()
	func() {
		defer recover() // 空操作
	}()
	func() {
		recover() // 空操作
	}()
	recover()       // 空操作
	defer recover() // 空操作
	panic("bye")
}
```



下面这个`recover`调用是有作用的：

```go
package main

func main() {
	defer func() {
		recover() // 将恢复恐慌"byte"
	}()

	panic("bye")
}
```



在下面的情况下，`recover`函数调用的返回值为`nil`：

- 传递给相应`panic`函数调用的实参为nil；
- 当前协程并没有处于恐慌状态；
- `recover`函数并未直接被一个延迟函数调用所直接调用，或者它直接被一个延迟函数调用所直接调用但是此延迟调用没有被和期望被恢复的恐慌相关联的函数调用所直接调用。



```go
// 此程序将带着未被恢复的恐慌1而崩溃退出。
package main

func demo() {
	defer func() {
		defer func() {
			recover() // 此调用将恢复恐慌2
		}()

		defer recover() // 空操作

		panic(2)
	}()
	panic(1)
}

func main() {
	demo()
}
```



每个`recover`调用都试图恢复当前协程中最新产生的且尚未恢复的恐慌，如果这个假设中的最新产生的且尚未恢复的恐慌不存在，则此`recover`调用是一个空操作。

Go运行时认为上例中的第二个`recover`调用试图恢复最新产生的尚未恢复的恐慌，即恐慌2。而此时和恐慌2相关联的函数调用为此第二个`recover`调用的直接调用者，即外层的延迟函数调用。此第二个`recover`调用并没有被外层的延迟函数调用所直接调用的某个延迟函数调用所调用；相反，它直接被外层的延迟函数调用所调用。这就是为什么此第二个`recover`调用是一个空操作的原因。

一个`recover`调用只有在它的直接外层调用（即`recover`调用的父调用）是一个延迟调用，并且此延迟调用（即父调用）的直接外层调用（即`recover`调用的爷调用）和当前协程中最新产生并且尚未恢复的恐慌相关联时才起作用。一个有效的`recover`调用将最新产生并且尚未恢复的恐慌和与此恐慌相关联的函数调用（即爷调用）剥离开来，并且返回当初传递给产生此恐慌的`panic`函数调用的参数。